2025-09-04 17:42:50,295 - discord.client - INFO - logging in using static token
2025-09-04 17:42:50,298 - bot - ERROR - Erreur OS lors du démarrage du serveur : [WinError 10022] Un argument non valide a été fourni
2025-09-04 17:42:50,800 - bot - ERROR - Erreur lors du chargement de cogs.inventaire : Extension 'cogs.inventaire' raised an error: ImportError: cannot import name 'CellNotFound' from 'gspread.exceptions' (C:\Users\freed\AppData\Local\Programs\Python\Python310\lib\site-packages\gspread\exceptions.py)
2025-09-04 17:42:51,333 - cards - ERROR - [CARDS] Traceback: Traceback (most recent call last):
  File "F:\Users\freed\Desktop\Citadelle-2.0\cogs\Cards.py", line 59, in __init__
    creds = Credentials.from_service_account_info(creds_info, scopes=[
  File "C:\Users\freed\AppData\Local\Programs\Python\Python310\lib\site-packages\google\oauth2\service_account.py", line 243, in from_service_account_info
    signer = _service_account_info.from_dict(
  File "C:\Users\freed\AppData\Local\Programs\Python\Python310\lib\site-packages\google\auth\_service_account_info.py", line 57, in from_dict
    signer = crypt.RSASigner.from_service_account_info(data)
  File "C:\Users\freed\AppData\Local\Programs\Python\Python310\lib\site-packages\google\auth\crypt\base.py", line 109, in from_service_account_info
    return cls.from_string(
  File "C:\Users\freed\AppData\Local\Programs\Python\Python310\lib\site-packages\google\auth\crypt\_python_rsa.py", line 173, in from_string
    raise exceptions.MalformedError("No key could be detected.")
google.auth.exceptions.MalformedError: No key could be detected.

2025-09-04 17:42:53,374 - bot - ERROR - Erreur lors du chargement de cogs.vocabulaire : Extension 'cogs.vocabulaire' raised an error: ModuleNotFoundError: No module named 'oauth2client'
2025-09-04 17:42:53,391 - bot - ERROR - Erreur lors du chargement de cogs.souselement : Extension 'cogs.souselement' raised an error: MalformedError: No key could be detected.
2025-09-04 17:42:53,429 - bot - ERROR - Erreur lors du chargement de cogs.excès : Extension 'cogs.excès' raised an error: MalformedError: No key could be detected.
2025-09-04 17:42:53,448 - root - ERROR - Erreur lors du chargement des credentials Google Sheets: No key could be detected.
2025-09-04 17:42:53,472 - bump_cog - ERROR - Traceback: Traceback (most recent call last):
  File "F:\Users\freed\Desktop\Citadelle-2.0\cogs\bump.py", line 71, in _async_setup
    self.sheet = await asyncio.wait_for(
  File "C:\Users\freed\AppData\Local\Programs\Python\Python310\lib\asyncio\tasks.py", line 445, in wait_for
    return fut.result()
  File "C:\Users\freed\AppData\Local\Programs\Python\Python310\lib\asyncio\threads.py", line 25, in to_thread
    return await loop.run_in_executor(None, func_call)
  File "C:\Users\freed\AppData\Local\Programs\Python\Python310\lib\concurrent\futures\thread.py", line 58, in run
    result = self.fn(*self.args, **self.kwargs)
  File "F:\Users\freed\Desktop\Citadelle-2.0\cogs\bump.py", line 62, in _build_service
    credentials = service_account.Credentials.from_service_account_info(
  File "C:\Users\freed\AppData\Local\Programs\Python\Python310\lib\site-packages\google\oauth2\service_account.py", line 243, in from_service_account_info
    signer = _service_account_info.from_dict(
  File "C:\Users\freed\AppData\Local\Programs\Python\Python310\lib\site-packages\google\auth\_service_account_info.py", line 57, in from_dict
    signer = crypt.RSASigner.from_service_account_info(data)
  File "C:\Users\freed\AppData\Local\Programs\Python\Python310\lib\site-packages\google\auth\crypt\base.py", line 109, in from_service_account_info
    return cls.from_string(
  File "C:\Users\freed\AppData\Local\Programs\Python\Python310\lib\site-packages\google\auth\crypt\_python_rsa.py", line 173, in from_string
    raise exceptions.MalformedError("No key could be detected.")
google.auth.exceptions.MalformedError: No key could be detected.

2025-09-12 19:21:41,445 - discord.client - INFO - logging in using static token
2025-09-12 19:21:43,268 - cards - ERROR - [CARDS] Traceback: Traceback (most recent call last):
  File "F:\Users\freed\Desktop\Citadelle-2.0\cogs\Cards.py", line 59, in __init__
    creds = Credentials.from_service_account_info(creds_info, scopes=[
  File "C:\Users\freed\AppData\Local\Programs\Python\Python310\lib\site-packages\google\oauth2\service_account.py", line 243, in from_service_account_info
    signer = _service_account_info.from_dict(
  File "C:\Users\freed\AppData\Local\Programs\Python\Python310\lib\site-packages\google\auth\_service_account_info.py", line 57, in from_dict
    signer = crypt.RSASigner.from_service_account_info(data)
  File "C:\Users\freed\AppData\Local\Programs\Python\Python310\lib\site-packages\google\auth\crypt\base.py", line 109, in from_service_account_info
    return cls.from_string(
  File "C:\Users\freed\AppData\Local\Programs\Python\Python310\lib\site-packages\google\auth\crypt\_python_rsa.py", line 173, in from_string
    raise exceptions.MalformedError("No key could be detected.")
google.auth.exceptions.MalformedError: No key could be detected.

2025-09-12 19:21:43,593 - cards - INFO - [CARDS] Cog Cards chargé avec succès
2025-09-12 19:21:45,192 - cogs.scene_surveillance - WARNING - Google Sheets non disponible: No key could be detected.
2025-09-12 19:21:45,192 - cogs.scene_surveillance - INFO - SceneSurveillance fonctionnera en mode dégradé (sans persistance)
2025-09-12 19:21:45,569 - bot - ERROR -    Type: ExtensionFailed
2025-09-12 19:21:45,569 - bot - ERROR -    Message: Extension 'cogs.souselement' raised an error: UnicodeEncodeError: 'charmap' codec can't encode characters in position 0-1: character maps to <undefined>
2025-09-12 19:21:45,591 - bot - ERROR -    Type: ExtensionFailed
2025-09-12 19:21:45,591 - bot - ERROR -    Message: Extension 'cogs.vocabulaire' raised an error: ModuleNotFoundError: No module named 'oauth2client'
2025-09-12 19:21:45,607 - bot - ERROR -    Type: ExtensionFailed
2025-09-12 19:21:45,607 - bot - ERROR -    Message: Extension 'cogs.excès' raised an error: UnicodeEncodeError: 'charmap' codec can't encode character '\u274c' in position 0: character maps to <undefined>
2025-09-12 19:21:45,648 - bot - ERROR -    Type: ExtensionFailed
2025-09-12 19:21:45,648 - bot - ERROR -    Message: Extension 'cogs.inventaire' raised an error: UnicodeEncodeError: 'charmap' codec can't encode character '\u274c' in position 0: character maps to <undefined>
2025-09-12 19:21:45,668 - bump_cog - ERROR - Traceback: Traceback (most recent call last):
  File "F:\Users\freed\Desktop\Citadelle-2.0\cogs\bump.py", line 74, in _async_setup
    self.sheet = await asyncio.wait_for(
  File "C:\Users\freed\AppData\Local\Programs\Python\Python310\lib\asyncio\tasks.py", line 445, in wait_for
    return fut.result()
  File "C:\Users\freed\AppData\Local\Programs\Python\Python310\lib\asyncio\threads.py", line 25, in to_thread
    return await loop.run_in_executor(None, func_call)
  File "C:\Users\freed\AppData\Local\Programs\Python\Python310\lib\concurrent\futures\thread.py", line 58, in run
    result = self.fn(*self.args, **self.kwargs)
  File "F:\Users\freed\Desktop\Citadelle-2.0\cogs\bump.py", line 65, in _build_service
    credentials = service_account.Credentials.from_service_account_info(
  File "C:\Users\freed\AppData\Local\Programs\Python\Python310\lib\site-packages\google\oauth2\service_account.py", line 243, in from_service_account_info
    signer = _service_account_info.from_dict(
  File "C:\Users\freed\AppData\Local\Programs\Python\Python310\lib\site-packages\google\auth\_service_account_info.py", line 57, in from_dict
    signer = crypt.RSASigner.from_service_account_info(data)
  File "C:\Users\freed\AppData\Local\Programs\Python\Python310\lib\site-packages\google\auth\crypt\base.py", line 109, in from_service_account_info
    return cls.from_string(
  File "C:\Users\freed\AppData\Local\Programs\Python\Python310\lib\site-packages\google\auth\crypt\_python_rsa.py", line 173, in from_string
    raise exceptions.MalformedError("No key could be detected.")
google.auth.exceptions.MalformedError: No key could be detected.

2025-09-12 19:21:46,260 - discord.gateway - INFO - Shard ID None has connected to Gateway (Session ID: c9df61d2ab3226c232de5574097ade01).
2025-09-12 19:53:51,030 - discord.client - INFO - logging in using static token
2025-09-12 19:53:51,823 - cards - ERROR - [CARDS] Traceback: Traceback (most recent call last):
  File "F:\Users\freed\Desktop\Citadelle-2.0\cogs\Cards.py", line 59, in __init__
    creds = Credentials.from_service_account_info(creds_info, scopes=[
  File "C:\Users\freed\AppData\Local\Programs\Python\Python310\lib\site-packages\google\oauth2\service_account.py", line 243, in from_service_account_info
    signer = _service_account_info.from_dict(
  File "C:\Users\freed\AppData\Local\Programs\Python\Python310\lib\site-packages\google\auth\_service_account_info.py", line 57, in from_dict
    signer = crypt.RSASigner.from_service_account_info(data)
  File "C:\Users\freed\AppData\Local\Programs\Python\Python310\lib\site-packages\google\auth\crypt\base.py", line 109, in from_service_account_info
    return cls.from_string(
  File "C:\Users\freed\AppData\Local\Programs\Python\Python310\lib\site-packages\google\auth\crypt\_python_rsa.py", line 173, in from_string
    raise exceptions.MalformedError("No key could be detected.")
google.auth.exceptions.MalformedError: No key could be detected.

2025-09-12 19:53:52,191 - cards - INFO - [CARDS] Cog Cards chargé avec succès
2025-09-12 19:53:53,947 - cogs.scene_surveillance - WARNING - Google Sheets non disponible: No key could be detected.
2025-09-12 19:53:53,947 - cogs.scene_surveillance - INFO - SceneSurveillance fonctionnera en mode dégradé (sans persistance)
2025-09-12 19:53:53,965 - bot - ERROR -    Type: ExtensionFailed
2025-09-12 19:53:53,965 - bot - ERROR -    Message: Extension 'cogs.souselement' raised an error: UnicodeEncodeError: 'charmap' codec can't encode characters in position 0-1: character maps to <undefined>
2025-09-12 19:53:53,971 - bot - ERROR -    Type: ExtensionFailed
2025-09-12 19:53:53,971 - bot - ERROR -    Message: Extension 'cogs.vocabulaire' raised an error: ModuleNotFoundError: No module named 'oauth2client'
2025-09-12 19:53:53,974 - bot - ERROR -    Type: ExtensionFailed
2025-09-12 19:53:53,974 - bot - ERROR -    Message: Extension 'cogs.excès' raised an error: UnicodeEncodeError: 'charmap' codec can't encode character '\u274c' in position 0: character maps to <undefined>
2025-09-12 19:53:53,982 - bot - ERROR -    Type: ExtensionFailed
2025-09-12 19:53:53,982 - bot - ERROR -    Message: Extension 'cogs.inventaire' raised an error: UnicodeEncodeError: 'charmap' codec can't encode character '\u274c' in position 0: character maps to <undefined>
2025-09-12 19:53:54,009 - bump_cog - ERROR - Traceback: Traceback (most recent call last):
  File "F:\Users\freed\Desktop\Citadelle-2.0\cogs\bump.py", line 74, in _async_setup
    self.sheet = await asyncio.wait_for(
  File "C:\Users\freed\AppData\Local\Programs\Python\Python310\lib\asyncio\tasks.py", line 445, in wait_for
    return fut.result()
  File "C:\Users\freed\AppData\Local\Programs\Python\Python310\lib\asyncio\threads.py", line 25, in to_thread
    return await loop.run_in_executor(None, func_call)
  File "C:\Users\freed\AppData\Local\Programs\Python\Python310\lib\concurrent\futures\thread.py", line 58, in run
    result = self.fn(*self.args, **self.kwargs)
  File "F:\Users\freed\Desktop\Citadelle-2.0\cogs\bump.py", line 65, in _build_service
    credentials = service_account.Credentials.from_service_account_info(
  File "C:\Users\freed\AppData\Local\Programs\Python\Python310\lib\site-packages\google\oauth2\service_account.py", line 243, in from_service_account_info
    signer = _service_account_info.from_dict(
  File "C:\Users\freed\AppData\Local\Programs\Python\Python310\lib\site-packages\google\auth\_service_account_info.py", line 57, in from_dict
    signer = crypt.RSASigner.from_service_account_info(data)
  File "C:\Users\freed\AppData\Local\Programs\Python\Python310\lib\site-packages\google\auth\crypt\base.py", line 109, in from_service_account_info
    return cls.from_string(
  File "C:\Users\freed\AppData\Local\Programs\Python\Python310\lib\site-packages\google\auth\crypt\_python_rsa.py", line 173, in from_string
    raise exceptions.MalformedError("No key could be detected.")
google.auth.exceptions.MalformedError: No key could be detected.

2025-09-12 19:53:54,555 - discord.gateway - INFO - Shard ID None has connected to Gateway (Session ID: 74033d3dcfb860bca7233a5a73a179f5).
2025-09-12 19:55:44,898 - discord.client - INFO - logging in using static token
2025-09-12 19:55:45,548 - cards - ERROR - [CARDS] Traceback: Traceback (most recent call last):
  File "F:\Users\freed\Desktop\Citadelle-2.0\cogs\Cards.py", line 59, in __init__
    creds = Credentials.from_service_account_info(creds_info, scopes=[
  File "C:\Users\freed\AppData\Local\Programs\Python\Python310\lib\site-packages\google\oauth2\service_account.py", line 243, in from_service_account_info
    signer = _service_account_info.from_dict(
  File "C:\Users\freed\AppData\Local\Programs\Python\Python310\lib\site-packages\google\auth\_service_account_info.py", line 57, in from_dict
    signer = crypt.RSASigner.from_service_account_info(data)
  File "C:\Users\freed\AppData\Local\Programs\Python\Python310\lib\site-packages\google\auth\crypt\base.py", line 109, in from_service_account_info
    return cls.from_string(
  File "C:\Users\freed\AppData\Local\Programs\Python\Python310\lib\site-packages\google\auth\crypt\_python_rsa.py", line 173, in from_string
    raise exceptions.MalformedError("No key could be detected.")
google.auth.exceptions.MalformedError: No key could be detected.

2025-09-12 19:55:45,810 - cards - INFO - [CARDS] Cog Cards chargé avec succès
2025-09-12 19:55:45,841 - cogs.scene_surveillance - WARNING - Google Sheets non disponible: No key could be detected.
2025-09-12 19:55:45,841 - cogs.scene_surveillance - INFO - SceneSurveillance fonctionnera en mode dégradé (sans persistance)
2025-09-12 19:55:45,860 - bot - ERROR -    Type: ExtensionFailed
2025-09-12 19:55:45,860 - bot - ERROR -    Message: Extension 'cogs.vocabulaire' raised an error: ValueError: No key could be detected.
2025-09-12 19:55:45,864 - bot - ERROR -    Type: ExtensionFailed
2025-09-12 19:55:45,864 - bot - ERROR -    Message: Extension 'cogs.excès' raised an error: MalformedError: No key could be detected.
2025-09-12 19:55:45,876 - bump_cog - ERROR - Traceback: Traceback (most recent call last):
  File "F:\Users\freed\Desktop\Citadelle-2.0\cogs\bump.py", line 74, in _async_setup
    self.sheet = await asyncio.wait_for(
  File "C:\Users\freed\AppData\Local\Programs\Python\Python310\lib\asyncio\tasks.py", line 445, in wait_for
    return fut.result()
  File "C:\Users\freed\AppData\Local\Programs\Python\Python310\lib\asyncio\threads.py", line 25, in to_thread
    return await loop.run_in_executor(None, func_call)
  File "C:\Users\freed\AppData\Local\Programs\Python\Python310\lib\concurrent\futures\thread.py", line 58, in run
    result = self.fn(*self.args, **self.kwargs)
  File "F:\Users\freed\Desktop\Citadelle-2.0\cogs\bump.py", line 65, in _build_service
    credentials = service_account.Credentials.from_service_account_info(
  File "C:\Users\freed\AppData\Local\Programs\Python\Python310\lib\site-packages\google\oauth2\service_account.py", line 243, in from_service_account_info
    signer = _service_account_info.from_dict(
  File "C:\Users\freed\AppData\Local\Programs\Python\Python310\lib\site-packages\google\auth\_service_account_info.py", line 57, in from_dict
    signer = crypt.RSASigner.from_service_account_info(data)
  File "C:\Users\freed\AppData\Local\Programs\Python\Python310\lib\site-packages\google\auth\crypt\base.py", line 109, in from_service_account_info
    return cls.from_string(
  File "C:\Users\freed\AppData\Local\Programs\Python\Python310\lib\site-packages\google\auth\crypt\_python_rsa.py", line 173, in from_string
    raise exceptions.MalformedError("No key could be detected.")
google.auth.exceptions.MalformedError: No key could be detected.

2025-09-12 19:55:46,845 - discord.gateway - INFO - Shard ID None has connected to Gateway (Session ID: 913cd5b5b7b4bb3de3758cbeaf954ae2).
