2025-09-04 17:42:53,472 - ERROR - Traceback: Traceback (most recent call last):
  File "F:\Users\freed\Desktop\Citadelle-2.0\cogs\bump.py", line 71, in _async_setup
    self.sheet = await asyncio.wait_for(
  File "C:\Users\freed\AppData\Local\Programs\Python\Python310\lib\asyncio\tasks.py", line 445, in wait_for
    return fut.result()
  File "C:\Users\freed\AppData\Local\Programs\Python\Python310\lib\asyncio\threads.py", line 25, in to_thread
    return await loop.run_in_executor(None, func_call)
  File "C:\Users\freed\AppData\Local\Programs\Python\Python310\lib\concurrent\futures\thread.py", line 58, in run
    result = self.fn(*self.args, **self.kwargs)
  File "F:\Users\freed\Desktop\Citadelle-2.0\cogs\bump.py", line 62, in _build_service
    credentials = service_account.Credentials.from_service_account_info(
  File "C:\Users\freed\AppData\Local\Programs\Python\Python310\lib\site-packages\google\oauth2\service_account.py", line 243, in from_service_account_info
    signer = _service_account_info.from_dict(
  File "C:\Users\freed\AppData\Local\Programs\Python\Python310\lib\site-packages\google\auth\_service_account_info.py", line 57, in from_dict
    signer = crypt.RSASigner.from_service_account_info(data)
  File "C:\Users\freed\AppData\Local\Programs\Python\Python310\lib\site-packages\google\auth\crypt\base.py", line 109, in from_service_account_info
    return cls.from_string(
  File "C:\Users\freed\AppData\Local\Programs\Python\Python310\lib\site-packages\google\auth\crypt\_python_rsa.py", line 173, in from_string
    raise exceptions.MalformedError("No key could be detected.")
google.auth.exceptions.MalformedError: No key could be detected.

2025-09-04 17:44:27,437 - ERROR - Erreur de configuration Google Sheets: SERVICE_ACCOUNT_JSON non défini
2025-09-04 17:44:27,439 - WARNING - Configuration Google Sheets manquante, fonctionnement en mode dégradé
2025-09-12 19:21:45,668 - ERROR - Traceback: Traceback (most recent call last):
  File "F:\Users\freed\Desktop\Citadelle-2.0\cogs\bump.py", line 74, in _async_setup
    self.sheet = await asyncio.wait_for(
  File "C:\Users\freed\AppData\Local\Programs\Python\Python310\lib\asyncio\tasks.py", line 445, in wait_for
    return fut.result()
  File "C:\Users\freed\AppData\Local\Programs\Python\Python310\lib\asyncio\threads.py", line 25, in to_thread
    return await loop.run_in_executor(None, func_call)
  File "C:\Users\freed\AppData\Local\Programs\Python\Python310\lib\concurrent\futures\thread.py", line 58, in run
    result = self.fn(*self.args, **self.kwargs)
  File "F:\Users\freed\Desktop\Citadelle-2.0\cogs\bump.py", line 65, in _build_service
    credentials = service_account.Credentials.from_service_account_info(
  File "C:\Users\freed\AppData\Local\Programs\Python\Python310\lib\site-packages\google\oauth2\service_account.py", line 243, in from_service_account_info
    signer = _service_account_info.from_dict(
  File "C:\Users\freed\AppData\Local\Programs\Python\Python310\lib\site-packages\google\auth\_service_account_info.py", line 57, in from_dict
    signer = crypt.RSASigner.from_service_account_info(data)
  File "C:\Users\freed\AppData\Local\Programs\Python\Python310\lib\site-packages\google\auth\crypt\base.py", line 109, in from_service_account_info
    return cls.from_string(
  File "C:\Users\freed\AppData\Local\Programs\Python\Python310\lib\site-packages\google\auth\crypt\_python_rsa.py", line 173, in from_string
    raise exceptions.MalformedError("No key could be detected.")
google.auth.exceptions.MalformedError: No key could be detected.

2025-09-12 19:53:54,009 - ERROR - Traceback: Traceback (most recent call last):
  File "F:\Users\freed\Desktop\Citadelle-2.0\cogs\bump.py", line 74, in _async_setup
    self.sheet = await asyncio.wait_for(
  File "C:\Users\freed\AppData\Local\Programs\Python\Python310\lib\asyncio\tasks.py", line 445, in wait_for
    return fut.result()
  File "C:\Users\freed\AppData\Local\Programs\Python\Python310\lib\asyncio\threads.py", line 25, in to_thread
    return await loop.run_in_executor(None, func_call)
  File "C:\Users\freed\AppData\Local\Programs\Python\Python310\lib\concurrent\futures\thread.py", line 58, in run
    result = self.fn(*self.args, **self.kwargs)
  File "F:\Users\freed\Desktop\Citadelle-2.0\cogs\bump.py", line 65, in _build_service
    credentials = service_account.Credentials.from_service_account_info(
  File "C:\Users\freed\AppData\Local\Programs\Python\Python310\lib\site-packages\google\oauth2\service_account.py", line 243, in from_service_account_info
    signer = _service_account_info.from_dict(
  File "C:\Users\freed\AppData\Local\Programs\Python\Python310\lib\site-packages\google\auth\_service_account_info.py", line 57, in from_dict
    signer = crypt.RSASigner.from_service_account_info(data)
  File "C:\Users\freed\AppData\Local\Programs\Python\Python310\lib\site-packages\google\auth\crypt\base.py", line 109, in from_service_account_info
    return cls.from_string(
  File "C:\Users\freed\AppData\Local\Programs\Python\Python310\lib\site-packages\google\auth\crypt\_python_rsa.py", line 173, in from_string
    raise exceptions.MalformedError("No key could be detected.")
google.auth.exceptions.MalformedError: No key could be detected.

